2021-05-14 13:09:13,739 ERROR: Exception on /login [GET] [in /home/adopat/myblog/venv/lib/python3.8/site-packages/flask/app.py:1891]
Traceback (most recent call last):
  File "/home/adopat/myblog/venv/lib/python3.8/site-packages/flask/app.py", line 2447, in wsgi_app
    response = self.full_dispatch_request()
  File "/home/adopat/myblog/venv/lib/python3.8/site-packages/flask/app.py", line 1952, in full_dispatch_request
    rv = self.handle_user_exception(e)
  File "/home/adopat/myblog/venv/lib/python3.8/site-packages/flask/app.py", line 1821, in handle_user_exception
    reraise(exc_type, exc_value, tb)
  File "/home/adopat/myblog/venv/lib/python3.8/site-packages/flask/_compat.py", line 39, in reraise
    raise value
  File "/home/adopat/myblog/venv/lib/python3.8/site-packages/flask/app.py", line 1950, in full_dispatch_request
    rv = self.dispatch_request()
  File "/home/adopat/myblog/venv/lib/python3.8/site-packages/flask/app.py", line 1936, in dispatch_request
    return self.view_functions[rule.endpoint](**req.view_args)
  File "/home/adopat/myblog/app/routes.py", line 62, in login
    return render_template('login.html', title='Sign In', form=form)
  File "/home/adopat/myblog/venv/lib/python3.8/site-packages/flask/templating.py", line 137, in render_template
    return _render(
  File "/home/adopat/myblog/venv/lib/python3.8/site-packages/flask/templating.py", line 120, in _render
    rv = template.render(context)
  File "/home/adopat/myblog/venv/lib/python3.8/site-packages/jinja2/environment.py", line 1090, in render
    self.environment.handle_exception()
  File "/home/adopat/myblog/venv/lib/python3.8/site-packages/jinja2/environment.py", line 832, in handle_exception
    reraise(*rewrite_traceback_stack(source=source))
  File "/home/adopat/myblog/venv/lib/python3.8/site-packages/jinja2/_compat.py", line 28, in reraise
    raise value.with_traceback(tb)
  File "/home/adopat/myblog/app/templates/login.html", line 2, in top-level template code
    {% extends "base.html" %}
  File "/home/adopat/myblog/venv/lib/python3.8/site-packages/jinja2/environment.py", line 832, in handle_exception
    reraise(*rewrite_traceback_stack(source=source))
  File "/home/adopat/myblog/venv/lib/python3.8/site-packages/jinja2/_compat.py", line 28, in reraise
    raise value.with_traceback(tb)
  File "/home/adopat/myblog/app/templates/base.html", line 76, in template
    {% block content %}
jinja2.exceptions.TemplateAssertionError: block 'content' defined twice
2021-05-14 13:11:15,616 INFO: Microblog startup [in /home/adopat/myblog/app/__init__.py:42]
2021-05-14 13:14:29,478 INFO: Microblog startup [in /home/adopat/myblog/app/__init__.py:42]
2021-05-14 13:14:59,704 INFO: Microblog startup [in /home/adopat/myblog/app/__init__.py:42]
2021-05-14 13:15:43,684 ERROR: Exception on /reset_password_request [POST] [in /home/adopat/myblog/venv/lib/python3.8/site-packages/flask/app.py:1891]
Traceback (most recent call last):
  File "/home/adopat/myblog/venv/lib/python3.8/site-packages/flask/app.py", line 2447, in wsgi_app
    response = self.full_dispatch_request()
  File "/home/adopat/myblog/venv/lib/python3.8/site-packages/flask/app.py", line 1952, in full_dispatch_request
    rv = self.handle_user_exception(e)
  File "/home/adopat/myblog/venv/lib/python3.8/site-packages/flask/app.py", line 1821, in handle_user_exception
    reraise(exc_type, exc_value, tb)
  File "/home/adopat/myblog/venv/lib/python3.8/site-packages/flask/_compat.py", line 39, in reraise
    raise value
  File "/home/adopat/myblog/venv/lib/python3.8/site-packages/flask/app.py", line 1950, in full_dispatch_request
    rv = self.dispatch_request()
  File "/home/adopat/myblog/venv/lib/python3.8/site-packages/flask/app.py", line 1936, in dispatch_request
    return self.view_functions[rule.endpoint](**req.view_args)
  File "/home/adopat/myblog/app/routes.py", line 166, in reset_password_request
    send_password_reset_email(user)
  File "/home/adopat/myblog/app/email.py", line 12, in send_password_reset_email
    token = user.get_reset_password_token()
  File "/home/adopat/myblog/app/models.py", line 57, in get_reset_password_token
    return jwt.encode(
AttributeError: 'str' object has no attribute 'decode'
